[E 240307 07:38:32 app:36] {'message': 'Something Went Wrong, Please Try After Sometime', 'errorcode': 'AB1004', 'status': False, 'data': None}
[E 240307 09:02:18 app:36] {'message': 'Something Went Wrong, Please Try After Sometime', 'errorcode': 'AB1004', 'status': False, 'data': None}
[E 240307 10:23:25 operations:100] Error fetching historical data: 'NoneType' object is not subscriptable
    Traceback (most recent call last):
      File "c:\Users\user\Documents\angleOne_trading\operations.py", line 97, in get_index_info
        index_open = index_historical_data['data'][0][1]
                     ~~~~~~~~~~~~~~~~~~~~~~~~~~~~~^^^
    TypeError: 'NoneType' object is not subscriptable
[E 240307 10:25:22 app:36] {'message': 'Something Went Wrong, Please Try After Sometime', 'errorcode': 'AB1004', 'status': False, 'data': None}
[E 240307 10:25:33 operations:101] Error fetching historical data: string index out of range
    Traceback (most recent call last):
      File "c:\Users\user\Documents\angleOne_trading\operations.py", line 98, in get_index_info
        index_open = index_historical_data['data'][0][1]
                     ~~~~~~~~~~~~~~~~~~~~~~~~~~~~~^^^
    IndexError: string index out of range
[E 240307 10:26:37 operations:101] Error fetching historical data: 'NoneType' object is not subscriptable
    Traceback (most recent call last):
      File "c:\Users\user\Documents\angleOne_trading\operations.py", line 98, in get_index_info
        index_open = index_historical_data['data'][0][1]
                     ~~~~~~~~~~~~~~~~~~~~~~~~~~~~~^^^
    TypeError: 'NoneType' object is not subscriptable
[E 240307 10:37:33 app:36] {'message': 'Something Went Wrong, Please Try After Sometime', 'errorcode': 'AB1004', 'status': False, 'data': None}
[E 240307 12:19:52 operations:199] Error fetching historical data: HTTPSConnectionPool(host='margincalculator.angelbroking.com', port=443): Max retries exceeded with url: /OpenAPI_File/files/OpenAPIScripMaster.json (Caused by ConnectTimeoutError(<urllib3.connection.HTTPSConnection object at 0x0000017E3F5A73D0>, 'Connection to margincalculator.angelbroking.com timed out. (connect timeout=None)'))
    Traceback (most recent call last):
      File "C:\Users\user\AppData\Local\Programs\Python\Python311\Lib\site-packages\urllib3\connection.py", line 203, in _new_conn
        sock = connection.create_connection(
               ^^^^^^^^^^^^^^^^^^^^^^^^^^^^^
      File "C:\Users\user\AppData\Local\Programs\Python\Python311\Lib\site-packages\urllib3\util\connection.py", line 85, in create_connection
        raise err
      File "C:\Users\user\AppData\Local\Programs\Python\Python311\Lib\site-packages\urllib3\util\connection.py", line 73, in create_connection
        sock.connect(sa)
    TimeoutError: [WinError 10060] A connection attempt failed because the connected party did not properly respond after a period of time, or established connection failed because connected host has failed to respond
    
    The above exception was the direct cause of the following exception:
    
    Traceback (most recent call last):
      File "C:\Users\user\AppData\Local\Programs\Python\Python311\Lib\site-packages\urllib3\connectionpool.py", line 791, in urlopen
        response = self._make_request(
                   ^^^^^^^^^^^^^^^^^^^
      File "C:\Users\user\AppData\Local\Programs\Python\Python311\Lib\site-packages\urllib3\connectionpool.py", line 492, in _make_request
        raise new_e
      File "C:\Users\user\AppData\Local\Programs\Python\Python311\Lib\site-packages\urllib3\connectionpool.py", line 468, in _make_request
        self._validate_conn(conn)
      File "C:\Users\user\AppData\Local\Programs\Python\Python311\Lib\site-packages\urllib3\connectionpool.py", line 1097, in _validate_conn
        conn.connect()
      File "C:\Users\user\AppData\Local\Programs\Python\Python311\Lib\site-packages\urllib3\connection.py", line 611, in connect
        self.sock = sock = self._new_conn()
                           ^^^^^^^^^^^^^^^^
      File "C:\Users\user\AppData\Local\Programs\Python\Python311\Lib\site-packages\urllib3\connection.py", line 212, in _new_conn
        raise ConnectTimeoutError(
    urllib3.exceptions.ConnectTimeoutError: (<urllib3.connection.HTTPSConnection object at 0x0000017E3F5A73D0>, 'Connection to margincalculator.angelbroking.com timed out. (connect timeout=None)')
    
    The above exception was the direct cause of the following exception:
    
    Traceback (most recent call last):
      File "C:\Users\user\AppData\Local\Programs\Python\Python311\Lib\site-packages\requests\adapters.py", line 486, in send
        resp = conn.urlopen(
               ^^^^^^^^^^^^^
      File "C:\Users\user\AppData\Local\Programs\Python\Python311\Lib\site-packages\urllib3\connectionpool.py", line 845, in urlopen
        retries = retries.increment(
                  ^^^^^^^^^^^^^^^^^^
      File "C:\Users\user\AppData\Local\Programs\Python\Python311\Lib\site-packages\urllib3\util\retry.py", line 515, in increment
        raise MaxRetryError(_pool, url, reason) from reason  # type: ignore[arg-type]
        ^^^^^^^^^^^^^^^^^^^^^^^^^^^^^^^^^^^^^^^^^^^^^^^^^^^
    urllib3.exceptions.MaxRetryError: HTTPSConnectionPool(host='margincalculator.angelbroking.com', port=443): Max retries exceeded with url: /OpenAPI_File/files/OpenAPIScripMaster.json (Caused by ConnectTimeoutError(<urllib3.connection.HTTPSConnection object at 0x0000017E3F5A73D0>, 'Connection to margincalculator.angelbroking.com timed out. (connect timeout=None)'))
    
    During handling of the above exception, another exception occurred:
    
    Traceback (most recent call last):
      File "c:\Users\user\Documents\angleOne_trading\operations.py", line 135, in get_strike_lowprice
        intializeSymbolTokenMap()
      File "c:\Users\user\Documents\angleOne_trading\operations.py", line 35, in intializeSymbolTokenMap
        d = requests.get(url).json()
            ^^^^^^^^^^^^^^^^^
      File "C:\Users\user\AppData\Local\Programs\Python\Python311\Lib\site-packages\requests\api.py", line 73, in get
        return request("get", url, params=params, **kwargs)
               ^^^^^^^^^^^^^^^^^^^^^^^^^^^^^^^^^^^^^^^^^^^^
      File "C:\Users\user\AppData\Local\Programs\Python\Python311\Lib\site-packages\requests\api.py", line 59, in request
        return session.request(method=method, url=url, **kwargs)
               ^^^^^^^^^^^^^^^^^^^^^^^^^^^^^^^^^^^^^^^^^^^^^^^^^
      File "C:\Users\user\AppData\Local\Programs\Python\Python311\Lib\site-packages\requests\sessions.py", line 589, in request
        resp = self.send(prep, **send_kwargs)
               ^^^^^^^^^^^^^^^^^^^^^^^^^^^^^^
      File "C:\Users\user\AppData\Local\Programs\Python\Python311\Lib\site-packages\requests\sessions.py", line 703, in send
        r = adapter.send(request, **kwargs)
            ^^^^^^^^^^^^^^^^^^^^^^^^^^^^^^^
      File "C:\Users\user\AppData\Local\Programs\Python\Python311\Lib\site-packages\requests\adapters.py", line 507, in send
        raise ConnectTimeout(e, request=request)
    requests.exceptions.ConnectTimeout: HTTPSConnectionPool(host='margincalculator.angelbroking.com', port=443): Max retries exceeded with url: /OpenAPI_File/files/OpenAPIScripMaster.json (Caused by ConnectTimeoutError(<urllib3.connection.HTTPSConnection object at 0x0000017E3F5A73D0>, 'Connection to margincalculator.angelbroking.com timed out. (connect timeout=None)'))
[E 240307 13:00:24 operations:100] Error fetching historical data: type object 'datetime.time' has no attribute 'sleep'
    Traceback (most recent call last):
      File "c:\Users\user\Documents\angleOne_trading\operations.py", line 64, in get_index_info
        wait_until_market_open(target_time)
      File "c:\Users\user\Documents\angleOne_trading\operations.py", line 28, in wait_until_market_open
        time.sleep(10)
        ^^^^^^^^^^
    AttributeError: type object 'datetime.time' has no attribute 'sleep'
