[E 240313 10:55:14 operations:107] Error fetching historical data: single positional indexer is out-of-bounds
    Traceback (most recent call last):
      File "c:\Users\user\Documents\angleOne_trading\operations.py", line 79, in get_index_info
        index_instrument_token = getTokenInfo('NSE','',index,'','','').iloc[0]['token']
                                 ~~~~~~~~~~~~~~~~~~~~~~~~~~~~~~~~~~~~~~~~~~^^^
      File "C:\Users\user\AppData\Local\Programs\Python\Python311\Lib\site-packages\pandas\core\indexing.py", line 1103, in __getitem__
        return self._getitem_axis(maybe_callable, axis=axis)
               ^^^^^^^^^^^^^^^^^^^^^^^^^^^^^^^^^^^^^^^^^^^^^
      File "C:\Users\user\AppData\Local\Programs\Python\Python311\Lib\site-packages\pandas\core\indexing.py", line 1656, in _getitem_axis
        self._validate_integer(key, axis)
      File "C:\Users\user\AppData\Local\Programs\Python\Python311\Lib\site-packages\pandas\core\indexing.py", line 1589, in _validate_integer
        raise IndexError("single positional indexer is out-of-bounds")
    IndexError: single positional indexer is out-of-bounds
[E 240313 11:01:14 operations:107] Error fetching historical data: single positional indexer is out-of-bounds
    Traceback (most recent call last):
      File "c:\Users\user\Documents\angleOne_trading\operations.py", line 79, in get_index_info
        index_instrument_token = getTokenInfo('NSE','',index,'','','').iloc[0]['token']
                                 ~~~~~~~~~~~~~~~~~~~~~~~~~~~~~~~~~~~~~~~~~~^^^
      File "C:\Users\user\AppData\Local\Programs\Python\Python311\Lib\site-packages\pandas\core\indexing.py", line 1103, in __getitem__
        return self._getitem_axis(maybe_callable, axis=axis)
               ^^^^^^^^^^^^^^^^^^^^^^^^^^^^^^^^^^^^^^^^^^^^^
      File "C:\Users\user\AppData\Local\Programs\Python\Python311\Lib\site-packages\pandas\core\indexing.py", line 1656, in _getitem_axis
        self._validate_integer(key, axis)
      File "C:\Users\user\AppData\Local\Programs\Python\Python311\Lib\site-packages\pandas\core\indexing.py", line 1589, in _validate_integer
        raise IndexError("single positional indexer is out-of-bounds")
    IndexError: single positional indexer is out-of-bounds
[E 240313 11:13:36 operations:109] Error fetching historical data: single positional indexer is out-of-bounds
    Traceback (most recent call last):
      File "c:\Users\user\Documents\angleOne_trading\operations.py", line 81, in get_index_info
        index_instrument_token = getTokenInfo('NSE','',index,'','','').iloc[0]['token']
                                 ~~~~~~~~~~~~~~~~~~~~~~~~~~~~~~~~~~~~~~~~~~^^^
      File "C:\Users\user\AppData\Local\Programs\Python\Python311\Lib\site-packages\pandas\core\indexing.py", line 1103, in __getitem__
        return self._getitem_axis(maybe_callable, axis=axis)
               ^^^^^^^^^^^^^^^^^^^^^^^^^^^^^^^^^^^^^^^^^^^^^
      File "C:\Users\user\AppData\Local\Programs\Python\Python311\Lib\site-packages\pandas\core\indexing.py", line 1656, in _getitem_axis
        self._validate_integer(key, axis)
      File "C:\Users\user\AppData\Local\Programs\Python\Python311\Lib\site-packages\pandas\core\indexing.py", line 1589, in _validate_integer
        raise IndexError("single positional indexer is out-of-bounds")
    IndexError: single positional indexer is out-of-bounds
[E 240313 11:17:41 operations:111] Error fetching historical data: name 'np' is not defined
    Traceback (most recent call last):
      File "c:\Users\user\Documents\angleOne_trading\operations.py", line 82, in get_index_info
        intializeSymbolTokenMap()
      File "c:\Users\user\Documents\angleOne_trading\operations.py", line 42, in intializeSymbolTokenMap
        token_df['expiry'] = token_df['expiry'].replace('', np.nan)
                                                            ^^
    NameError: name 'np' is not defined
[E 240313 11:18:40 operations:112] Error fetching historical data: single positional indexer is out-of-bounds
    Traceback (most recent call last):
      File "c:\Users\user\Documents\angleOne_trading\operations.py", line 84, in get_index_info
        index_instrument_token = getTokenInfo('NSE','',index,'','','').iloc[0]['token']
                                 ~~~~~~~~~~~~~~~~~~~~~~~~~~~~~~~~~~~~~~~~~~^^^
      File "C:\Users\user\AppData\Local\Programs\Python\Python311\Lib\site-packages\pandas\core\indexing.py", line 1103, in __getitem__
        return self._getitem_axis(maybe_callable, axis=axis)
               ^^^^^^^^^^^^^^^^^^^^^^^^^^^^^^^^^^^^^^^^^^^^^
      File "C:\Users\user\AppData\Local\Programs\Python\Python311\Lib\site-packages\pandas\core\indexing.py", line 1656, in _getitem_axis
        self._validate_integer(key, axis)
      File "C:\Users\user\AppData\Local\Programs\Python\Python311\Lib\site-packages\pandas\core\indexing.py", line 1589, in _validate_integer
        raise IndexError("single positional indexer is out-of-bounds")
    IndexError: single positional indexer is out-of-bounds
[E 240313 11:23:49 operations:115] Error fetching historical data: single positional indexer is out-of-bounds
    Traceback (most recent call last):
      File "c:\Users\user\Documents\angleOne_trading\operations.py", line 87, in get_index_info
        index_instrument_token = getTokenInfo('NSE','',index,'','','').iloc[0]['token']
                                 ~~~~~~~~~~~~~~~~~~~~~~~~~~~~~~~~~~~~~~~~~~^^^
      File "C:\Users\user\AppData\Local\Programs\Python\Python311\Lib\site-packages\pandas\core\indexing.py", line 1103, in __getitem__
        return self._getitem_axis(maybe_callable, axis=axis)
               ^^^^^^^^^^^^^^^^^^^^^^^^^^^^^^^^^^^^^^^^^^^^^
      File "C:\Users\user\AppData\Local\Programs\Python\Python311\Lib\site-packages\pandas\core\indexing.py", line 1656, in _getitem_axis
        self._validate_integer(key, axis)
      File "C:\Users\user\AppData\Local\Programs\Python\Python311\Lib\site-packages\pandas\core\indexing.py", line 1589, in _validate_integer
        raise IndexError("single positional indexer is out-of-bounds")
    IndexError: single positional indexer is out-of-bounds
[E 240313 11:37:52 operations:131] Error fetching historical data: single positional indexer is out-of-bounds
    Traceback (most recent call last):
      File "c:\Users\user\Documents\angleOne_trading\operations.py", line 103, in get_index_info
        index_instrument_token = getTokenInfo('NSE','',index,'','','').iloc[0]['token']
                                 ~~~~~~~~~~~~~~~~~~~~~~~~~~~~~~~~~~~~~~~~~~^^^
      File "C:\Users\user\AppData\Local\Programs\Python\Python311\Lib\site-packages\pandas\core\indexing.py", line 1103, in __getitem__
        return self._getitem_axis(maybe_callable, axis=axis)
               ^^^^^^^^^^^^^^^^^^^^^^^^^^^^^^^^^^^^^^^^^^^^^
      File "C:\Users\user\AppData\Local\Programs\Python\Python311\Lib\site-packages\pandas\core\indexing.py", line 1656, in _getitem_axis
        self._validate_integer(key, axis)
      File "C:\Users\user\AppData\Local\Programs\Python\Python311\Lib\site-packages\pandas\core\indexing.py", line 1589, in _validate_integer
        raise IndexError("single positional indexer is out-of-bounds")
    IndexError: single positional indexer is out-of-bounds
[E 240313 11:41:10 operations:131] Error fetching historical data: name 'logging' is not defined
    Traceback (most recent call last):
      File "c:\Users\user\Documents\angleOne_trading\operations.py", line 102, in get_index_info
        intializeSymbolTokenMap()
      File "c:\Users\user\Documents\angleOne_trading\operations.py", line 50, in intializeSymbolTokenMap
        logging.warning("Rows with empty strings in the 'expiry' column:")
        ^^^^^^^
    NameError: name 'logging' is not defined
[E 240313 11:58:11 operations:126] Error fetching historical data: single positional indexer is out-of-bounds
    Traceback (most recent call last):
      File "c:\Users\user\Documents\angleOne_trading\operations.py", line 98, in get_index_info
        index_instrument_token = getTokenInfo('NSE','',index,'','','').iloc[0]['token']
                                 ~~~~~~~~~~~~~~~~~~~~~~~~~~~~~~~~~~~~~~~~~~^^^
      File "C:\Users\user\AppData\Local\Programs\Python\Python311\Lib\site-packages\pandas\core\indexing.py", line 1103, in __getitem__
        return self._getitem_axis(maybe_callable, axis=axis)
               ^^^^^^^^^^^^^^^^^^^^^^^^^^^^^^^^^^^^^^^^^^^^^
      File "C:\Users\user\AppData\Local\Programs\Python\Python311\Lib\site-packages\pandas\core\indexing.py", line 1656, in _getitem_axis
        self._validate_integer(key, axis)
      File "C:\Users\user\AppData\Local\Programs\Python\Python311\Lib\site-packages\pandas\core\indexing.py", line 1589, in _validate_integer
        raise IndexError("single positional indexer is out-of-bounds")
    IndexError: single positional indexer is out-of-bounds
