[E 240422 10:01:19 operations:106] Error fetching historical data: HTTPSConnectionPool(host='apiconnect.angelbroking.com', port=443): Max retries exceeded with url: /rest/secure/angelbroking/historical/v1/getCandleData (Caused by ConnectTimeoutError(<urllib3.connection.HTTPSConnection object at 0x000001C3C9801950>, 'Connection to apiconnect.angelbroking.com timed out. (connect timeout=7)'))
    Traceback (most recent call last):
      File "C:\Users\user\Documents\angleOne_trading\myenv\Lib\site-packages\urllib3\connection.py", line 203, in _new_conn
        sock = connection.create_connection(
               ^^^^^^^^^^^^^^^^^^^^^^^^^^^^^
      File "C:\Users\user\Documents\angleOne_trading\myenv\Lib\site-packages\urllib3\util\connection.py", line 85, in create_connection
        raise err
      File "C:\Users\user\Documents\angleOne_trading\myenv\Lib\site-packages\urllib3\util\connection.py", line 73, in create_connection
        sock.connect(sa)
    TimeoutError: timed out
    
    The above exception was the direct cause of the following exception:
    
    Traceback (most recent call last):
      File "C:\Users\user\Documents\angleOne_trading\myenv\Lib\site-packages\urllib3\connectionpool.py", line 790, in urlopen
        response = self._make_request(
                   ^^^^^^^^^^^^^^^^^^^
      File "C:\Users\user\Documents\angleOne_trading\myenv\Lib\site-packages\urllib3\connectionpool.py", line 491, in _make_request
        raise new_e
      File "C:\Users\user\Documents\angleOne_trading\myenv\Lib\site-packages\urllib3\connectionpool.py", line 467, in _make_request
        self._validate_conn(conn)
      File "C:\Users\user\Documents\angleOne_trading\myenv\Lib\site-packages\urllib3\connectionpool.py", line 1096, in _validate_conn
        conn.connect()
      File "C:\Users\user\Documents\angleOne_trading\myenv\Lib\site-packages\urllib3\connection.py", line 611, in connect
        self.sock = sock = self._new_conn()
                           ^^^^^^^^^^^^^^^^
      File "C:\Users\user\Documents\angleOne_trading\myenv\Lib\site-packages\urllib3\connection.py", line 212, in _new_conn
        raise ConnectTimeoutError(
    urllib3.exceptions.ConnectTimeoutError: (<urllib3.connection.HTTPSConnection object at 0x000001C3C9801950>, 'Connection to apiconnect.angelbroking.com timed out. (connect timeout=7)')
    
    The above exception was the direct cause of the following exception:
    
    Traceback (most recent call last):
      File "C:\Users\user\Documents\angleOne_trading\myenv\Lib\site-packages\requests\adapters.py", line 486, in send
        resp = conn.urlopen(
               ^^^^^^^^^^^^^
      File "C:\Users\user\Documents\angleOne_trading\myenv\Lib\site-packages\urllib3\connectionpool.py", line 844, in urlopen
        retries = retries.increment(
                  ^^^^^^^^^^^^^^^^^^
      File "C:\Users\user\Documents\angleOne_trading\myenv\Lib\site-packages\urllib3\util\retry.py", line 515, in increment
        raise MaxRetryError(_pool, url, reason) from reason  # type: ignore[arg-type]
        ^^^^^^^^^^^^^^^^^^^^^^^^^^^^^^^^^^^^^^^^^^^^^^^^^^^
    urllib3.exceptions.MaxRetryError: HTTPSConnectionPool(host='apiconnect.angelbroking.com', port=443): Max retries exceeded with url: /rest/secure/angelbroking/historical/v1/getCandleData (Caused by ConnectTimeoutError(<urllib3.connection.HTTPSConnection object at 0x000001C3C9801950>, 'Connection to apiconnect.angelbroking.com timed out. (connect timeout=7)'))
    
    During handling of the above exception, another exception occurred:
    
    Traceback (most recent call last):
      File "c:\Users\user\Documents\angleOne_trading\operations.py", line 101, in get_index_info
        index_historical_data = smartApi.getCandleData(params)
                                ^^^^^^^^^^^^^^^^^^^^^^^^^^^^^^
      File "C:\Users\user\Documents\angleOne_trading\myenv\Lib\site-packages\SmartApi\smartConnect.py", line 430, in getCandleData
        getCandleDataResponse=self._postRequest("api.candle.data",historicDataParams)
                              ^^^^^^^^^^^^^^^^^^^^^^^^^^^^^^^^^^^^^^^^^^^^^^^^^^^^^^^
      File "C:\Users\user\Documents\angleOne_trading\myenv\Lib\site-packages\SmartApi\smartConnect.py", line 228, in _postRequest
        return self._request(route, "POST", params)
               ^^^^^^^^^^^^^^^^^^^^^^^^^^^^^^^^^^^^
      File "C:\Users\user\Documents\angleOne_trading\myenv\Lib\site-packages\SmartApi\smartConnect.py", line 188, in _request
        raise e
      File "C:\Users\user\Documents\angleOne_trading\myenv\Lib\site-packages\SmartApi\smartConnect.py", line 177, in _request
        r = requests.request(method,
            ^^^^^^^^^^^^^^^^^^^^^^^^
      File "C:\Users\user\Documents\angleOne_trading\myenv\Lib\site-packages\requests\api.py", line 59, in request
        return session.request(method=method, url=url, **kwargs)
               ^^^^^^^^^^^^^^^^^^^^^^^^^^^^^^^^^^^^^^^^^^^^^^^^^
      File "C:\Users\user\Documents\angleOne_trading\myenv\Lib\site-packages\requests\sessions.py", line 589, in request
        resp = self.send(prep, **send_kwargs)
               ^^^^^^^^^^^^^^^^^^^^^^^^^^^^^^
      File "C:\Users\user\Documents\angleOne_trading\myenv\Lib\site-packages\requests\sessions.py", line 703, in send
        r = adapter.send(request, **kwargs)
            ^^^^^^^^^^^^^^^^^^^^^^^^^^^^^^^
      File "C:\Users\user\Documents\angleOne_trading\myenv\Lib\site-packages\requests\adapters.py", line 507, in send
        raise ConnectTimeout(e, request=request)
    requests.exceptions.ConnectTimeout: HTTPSConnectionPool(host='apiconnect.angelbroking.com', port=443): Max retries exceeded with url: /rest/secure/angelbroking/historical/v1/getCandleData (Caused by ConnectTimeoutError(<urllib3.connection.HTTPSConnection object at 0x000001C3C9801950>, 'Connection to apiconnect.angelbroking.com timed out. (connect timeout=7)'))
