[E 240221 10:05:41 smartConnect:479] Error occurred in ind_order_details: ('Connection aborted.', ConnectionResetError(10054, 'An existing connection was forcibly closed by the remote host', None, 10054, None))
[E 240221 13:04:29 operations:162] Error fetching historical data: HTTPSConnectionPool(host='apiconnect.angelbroking.com', port=443): Read timed out. (read timeout=7)
    Traceback (most recent call last):
      File "C:\Users\user\AppData\Local\Programs\Python\Python311\Lib\site-packages\urllib3\connectionpool.py", line 468, in _make_request
        self._validate_conn(conn)
      File "C:\Users\user\AppData\Local\Programs\Python\Python311\Lib\site-packages\urllib3\connectionpool.py", line 1097, in _validate_conn
        conn.connect()
      File "C:\Users\user\AppData\Local\Programs\Python\Python311\Lib\site-packages\urllib3\connection.py", line 642, in connect
        sock_and_verified = _ssl_wrap_socket_and_match_hostname(
                            ^^^^^^^^^^^^^^^^^^^^^^^^^^^^^^^^^^^^
      File "C:\Users\user\AppData\Local\Programs\Python\Python311\Lib\site-packages\urllib3\connection.py", line 783, in _ssl_wrap_socket_and_match_hostname
        ssl_sock = ssl_wrap_socket(
                   ^^^^^^^^^^^^^^^^
      File "C:\Users\user\AppData\Local\Programs\Python\Python311\Lib\site-packages\urllib3\util\ssl_.py", line 471, in ssl_wrap_socket
        ssl_sock = _ssl_wrap_socket_impl(sock, context, tls_in_tls, server_hostname)
                   ^^^^^^^^^^^^^^^^^^^^^^^^^^^^^^^^^^^^^^^^^^^^^^^^^^^^^^^^^^^^^^^^^
      File "C:\Users\user\AppData\Local\Programs\Python\Python311\Lib\site-packages\urllib3\util\ssl_.py", line 515, in _ssl_wrap_socket_impl
        return ssl_context.wrap_socket(sock, server_hostname=server_hostname)
               ^^^^^^^^^^^^^^^^^^^^^^^^^^^^^^^^^^^^^^^^^^^^^^^^^^^^^^^^^^^^^^
      File "C:\Users\user\AppData\Local\Programs\Python\Python311\Lib\ssl.py", line 517, in wrap_socket
        return self.sslsocket_class._create(
               ^^^^^^^^^^^^^^^^^^^^^^^^^^^^^
      File "C:\Users\user\AppData\Local\Programs\Python\Python311\Lib\ssl.py", line 1075, in _create
        self.do_handshake()
      File "C:\Users\user\AppData\Local\Programs\Python\Python311\Lib\ssl.py", line 1346, in do_handshake
        self._sslobj.do_handshake()
    TimeoutError: _ssl.c:975: The handshake operation timed out
    
    The above exception was the direct cause of the following exception:
    
    Traceback (most recent call last):
      File "C:\Users\user\AppData\Local\Programs\Python\Python311\Lib\site-packages\requests\adapters.py", line 486, in send
        resp = conn.urlopen(
               ^^^^^^^^^^^^^
      File "C:\Users\user\AppData\Local\Programs\Python\Python311\Lib\site-packages\urllib3\connectionpool.py", line 845, in urlopen
        retries = retries.increment(
                  ^^^^^^^^^^^^^^^^^^
      File "C:\Users\user\AppData\Local\Programs\Python\Python311\Lib\site-packages\urllib3\util\retry.py", line 470, in increment
        raise reraise(type(error), error, _stacktrace)
              ^^^^^^^^^^^^^^^^^^^^^^^^^^^^^^^^^^^^^^^^
      File "C:\Users\user\AppData\Local\Programs\Python\Python311\Lib\site-packages\urllib3\util\util.py", line 39, in reraise
        raise value
      File "C:\Users\user\AppData\Local\Programs\Python\Python311\Lib\site-packages\urllib3\connectionpool.py", line 791, in urlopen
        response = self._make_request(
                   ^^^^^^^^^^^^^^^^^^^
      File "C:\Users\user\AppData\Local\Programs\Python\Python311\Lib\site-packages\urllib3\connectionpool.py", line 492, in _make_request
        raise new_e
      File "C:\Users\user\AppData\Local\Programs\Python\Python311\Lib\site-packages\urllib3\connectionpool.py", line 470, in _make_request
        self._raise_timeout(err=e, url=url, timeout_value=conn.timeout)
      File "C:\Users\user\AppData\Local\Programs\Python\Python311\Lib\site-packages\urllib3\connectionpool.py", line 371, in _raise_timeout
        raise ReadTimeoutError(
    urllib3.exceptions.ReadTimeoutError: HTTPSConnectionPool(host='apiconnect.angelbroking.com', port=443): Read timed out. (read timeout=7)
    
    During handling of the above exception, another exception occurred:
    
    Traceback (most recent call last):
      File "c:\Users\user\Documents\angleOne_trading\operations.py", line 154, in get_strike_lowprice
        index_historical_data = smartApi.getCandleData(params_ce_pe)
                                ^^^^^^^^^^^^^^^^^^^^^^^^^^^^^^^^^^^^
      File "C:\Users\user\AppData\Local\Programs\Python\Python311\Lib\site-packages\SmartApi\smartConnect.py", line 430, in getCandleData
        getCandleDataResponse=self._postRequest("api.candle.data",historicDataParams)
                              ^^^^^^^^^^^^^^^^^^^^^^^^^^^^^^^^^^^^^^^^^^^^^^^^^^^^^^^
      File "C:\Users\user\AppData\Local\Programs\Python\Python311\Lib\site-packages\SmartApi\smartConnect.py", line 228, in _postRequest
        return self._request(route, "POST", params)
               ^^^^^^^^^^^^^^^^^^^^^^^^^^^^^^^^^^^^
      File "C:\Users\user\AppData\Local\Programs\Python\Python311\Lib\site-packages\SmartApi\smartConnect.py", line 188, in _request
        raise e
      File "C:\Users\user\AppData\Local\Programs\Python\Python311\Lib\site-packages\SmartApi\smartConnect.py", line 177, in _request
        r = requests.request(method,
            ^^^^^^^^^^^^^^^^^^^^^^^^
      File "C:\Users\user\AppData\Local\Programs\Python\Python311\Lib\site-packages\requests\api.py", line 59, in request
        return session.request(method=method, url=url, **kwargs)
               ^^^^^^^^^^^^^^^^^^^^^^^^^^^^^^^^^^^^^^^^^^^^^^^^^
      File "C:\Users\user\AppData\Local\Programs\Python\Python311\Lib\site-packages\requests\sessions.py", line 589, in request
        resp = self.send(prep, **send_kwargs)
               ^^^^^^^^^^^^^^^^^^^^^^^^^^^^^^
      File "C:\Users\user\AppData\Local\Programs\Python\Python311\Lib\site-packages\requests\sessions.py", line 703, in send
        r = adapter.send(request, **kwargs)
            ^^^^^^^^^^^^^^^^^^^^^^^^^^^^^^^
      File "C:\Users\user\AppData\Local\Programs\Python\Python311\Lib\site-packages\requests\adapters.py", line 532, in send
        raise ReadTimeout(e, request=request)
    requests.exceptions.ReadTimeout: HTTPSConnectionPool(host='apiconnect.angelbroking.com', port=443): Read timed out. (read timeout=7)
